Workbook
Name Slicer_Player_2: #N/A
Name Slicer_Position1: #N/A
Name Slicer_Time: #N/A

Sheet Team Report
I9: #VALUE! | R9: #VALUE! | V9: SUBSITITUTE | Y9: SCORED | AA9: LOST
F11: =Dashboard!P4 -> 51.342596 | M11: =Dashboard!M4 -> 4 | P11: =Dashboard!N4 -> 4
F13: Minutes
F15: P'Boro | I15: =Dashboard!V4 -> 0.60437951 | T15: =Dashboard!W4 -> 0.39562049 | V15: Opponent
C16: P'Boro Final 1/3 | Y16: Opponent Final 1/3
C17: In play Final 1/3 | Y17: In play Final 1/3
C18: =Dashboard!DT4 -> 28 | F18: P'Boro | I18: =Dashboard!DS4 -> 35 | T18: =Dashboard!DU4 -> 54 | V18: Opponent | Y18: =Dashboard!DV4 -> 24
C19: Throw in Final 1/3 | Y19: Throw in Final 1/3
C20: =Dashboard!DF4 -> 6 | Y20: =Dashboard!DL4 -> 9
C21: Transition in Final 1/3 | F21: P'Boro | I21: =Dashboard!DX4 -> 13 | T21: =Dashboard!DY4 -> 18 | V21: Opponent | Y21: Transition in Final 1/3
C22: =Dashboard!CU4 -> 1 | Y22: =Dashboard!DB4 -> 21
D23: Details | G23: Chance Type | J23: P'Boro Chances | P23: Opponent Chances | U23: Chance Type | X23: Details
D24: Crossing to Shots | G24: Chance from Open Play | M24: =Dashboard!X4 -> 12 | P24: =Dashboard!AN4 -> 25 | U24: Opp Chance from Open Play | X24: Crossing to Opp Shots
D25: =Dashboard!AH4 -> 2 | G25: =Dashboard!AG4 -> 4 | U25: =Dashboard!AW4 -> 4 | X25: =Dashboard!AX4 -> 4 | AC25: =L27/$L$26 -> 0.45454545
D26: Counterattack to Shots | G26: Chance from Transition | L26: =SUM(L27:L29) -> 11 | M26: Total Shots | P26: Total Shots | R26: =SUM(R27:R29) -> 23 | U26: Opp Chance from Transition | X26: Counterattack to Opp Shots | AC26: =L28/$L$26 -> 0.27272727
D27: =Dashboard!AI4 -> 3 | G27: =Dashboard!AK4 -> 5 | L27: =Dashboard!Z4 -> 5 | M27: On Target | P27: On Target | R27: =Dashboard!AP4 -> 10 | U27: =Dashboard!BA4 -> 17 | X27: =Dashboard!AY4 -> 2 | AC27: =L29/$L$26 -> 0.27272727
D28: Through pass to Shots | G28: Chance from Set Play | L28: =Dashboard!AA4 -> 3 | M28: Off Target | P28: Off Target | R28: =Dashboard!AQ4 -> 10 | U28: Opp Chance from Set Play | X28: Through pass to Opp Shots
D29: =Dashboard!AJ4 -> 3 | G29: =Dashboard!AL4 -> 1 | L29: =Dashboard!AB4 -> 3 | M29: Blocked | P29: Blocked | R29: =Dashboard!AR4 -> 3 | U29: =Dashboard!BB4 -> 2 | X29: =Dashboard!AZ4 -> 3
G30: Chance from Restart | L30: =Dashboard!AF4 -> 8 | M30: Shots in the box | P30: Shots in the box | R30: =Dashboard!AV4 -> 12 | U30: Opp Chance from Restart
G31: =Dashboard!AM4 -> 2 | U31: =Dashboard!BC4 -> 2
D32: Create the Attack | I32: Build up | Q32: High Block | X32: Mid Block
D33: =Dashboard!BL4 -> 42 | F33: Total | I33: =Dashboard!BI4 -> 15 | J33: Turnovers | L33: =Dashboard!BD4 -> 47 | M33: Total | Q33: Total | S33: =Dashboard!CA4 -> 3 | T33: Regain Opp Half | V33: =Dashboard!CF4 -> 1 | X33: Total | Z33: =Dashboard!CI4 -> 7
D34: =Dashboard!BM4 -> 12 | F34: Successful | I34: =Dashboard!BJ4 -> 18 | J34: Direct Play | L34: =Dashboard!BE4 -> 18 | M34: Successful | Q34: Successful | S34: =Dashboard!CB4 -> 2 | T34: Force error | V34: =Dashboard!CG4 -> 1 | X34: Successful | Z34: =Dashboard!CJ4 -> 5
D35: =Dashboard!BN4 -> 30 | F35: Unsuccessful | I35: =Dashboard!BK4 -> 12 | J35: Reach Opp Half | L35: =Dashboard!BF4 -> 29 | M35: Unsuccessful | Q35: Unsuccessful | S35: =Dashboard!CC4 -> 1 | T35: Opp Direct Play | V35: =Dashboard!CH4 -> 1 | X35: Unsuccessful | Z35: =Dashboard!CK4 -> 2
E37: Offside | L37: Cross | Q37: Cross | X37: Low Block
E38: =COUNTIF('Raw data'!D:D,"P'Boro Offside") -> 2 | F38: P'Boro | L38: =Dashboard!BQ4 -> 11 | M38: Total | Q38: Total | S38: =Dashboard!BV4 -> 14 | X38: Total | Z38: =Dashboard!CN4 -> 5
E39: =COUNTIF('Raw data'!D:D,"Opp Offside") -> 6 | F39: Opponent | L39: =Dashboard!BR4 -> 3 | M39: Successful | Q39: Successful | S39: =Dashboard!BW4 -> 7 | X39: Successful | Z39: =Dashboard!CO4 -> 4
L40: =Dashboard!BS4 -> 8 | M40: Unsuccessful | Q40: Unsuccessful | S40: =Dashboard!BX4 -> 7 | X40: Unsuccessful | Z40: =Dashboard!CP4 -> 1
E41: Villa Set Plays | J41: Transition to Attack | Q41: Opp Transition to Attack | W41: Opp Set Plays
C42: Throw in Succ % | E42: =Dashboard!DC4 -> 1 | F42: P'Boro Corner | K42: =Dashboard!CS4 -> 69 | L42: Transition to Attack | Q42: Transition to Attack | T42: =Dashboard!CX4 -> 75 | W42: P'Boro Corner | Z42: =Dashboard!DD4 -> 5 | AA42: Throw in Succ %
C43: =SUM(Dashboard!DF4:DH4) -> 12 | D43: =C43/E43 -> 1 | E43: =Dashboard!DE4 -> 12 | F43: P'Boro Throw in | J43: =K43/$K$42 -> 0.014492754 | K43: =Dashboard!CU4 -> 1 | L43: Final Third | Q43: Final Third | T43: =Dashboard!DB4 -> 21 | U43: =T43/$T$42 -> 0.28 | W43: P'Boro Throw in | Z43: =Dashboard!DI4 -> 24 | AA43: =AB43/Z43 -> 1 | AB43: =SUM(Dashboard!DJ4:DL4) -> 24
E44: =Dashboard!DM4 -> 12 | F44: P'Boro Free Kick | J44: =K44/$K$42 -> 0.39130435 | K44: =Dashboard!CV4 -> 27 | L44: Middle Third | Q44: Middle Third | T44: =Dashboard!DA4 -> 30 | U44: =T44/$T$42 -> 0.4 | W44: P'Boro Free Kick | Z44: =Dashboard!DO4 -> 10
E45: =Dashboard!DQ4 -> 15 | F45: P'Boro Goal Kick | J45: =K45/$K$42 -> 0.5942029 | K45: =Dashboard!CW4 -> 41 | L45: Own Third | Q45: Own Third | T45: =Dashboard!CZ4 -> 24 | U45: =T45/$T$42 -> 0.32 | W45: P'Boro Goal Kick | Z45: =Dashboard!DR4 -> 9
K46: =Dashboard!CT4 -> 5 | L46: Counterattack | Q46: Counterattack | T46: =Dashboard!CY4 -> 6
D47: Backward Passes | H47: Forward Passes | L47: Total Passes | Q47: Defensive duel | U47: Aerial duel | Y47: Defensive Position
D48: =Dashboard!EP4 -> 105 | E48: =Dashboard!EQ4 -> 100 | F48: =E48/D48 -> 0.95238095 | H48: =Dashboard!EF4 -> 193 | I48: =Dashboard!EG4 -> 116 | J48: =I48/H48 -> 0.60103627 | L48: =Dashboard!EA4 -> 388 | M48: =Dashboard!EB4 -> 293 | N48: =M48/L48 -> 0.75515464 | Q48: =Dashboard!HA4 -> 35 | R48: =Dashboard!HB4 -> 11 | S48: =R48/Q48 -> 0.31428571 | U48: =Dashboard!HF4 -> 20 | V48: =Dashboard!HG4 -> 11 | W48: =V48/U48 -> 0.55 | Y48: Interception | AA48: =Dashboard!IA4 -> 26
Y49: Clearnace | AA49: =Dashboard!HZ4 -> 11
C50: Ball Lost | H50: Lateral Passes | L50: Long Passes | Q50: Tackles | U50: Loose Ball duel | Y50: Recovery | AA50: =Dashboard!IC4 -> 13
C51: Total Ball Lost | E51: =Dashboard!FO4 -> 31 | H51: =Dashboard!EK4 -> 90 | I51: =Dashboard!EL4 -> 77 | J51: =I51/H51 -> 0.85555556 | L51: =Dashboard!EU4 -> 43 | M51: =Dashboard!EV4 -> 20 | N51: =M51/L51 -> 0.46511628 | Q51: =Dashboard!HP4 -> 9 | R51: =Dashboard!HQ4 -> 9 | S51: =R51/Q51 -> 1 | U51: =Dashboard!HU4 -> 15 | V51: =Dashboard!HV4 -> 8 | W51: =V51/U51 -> 0.53333333 | Y51: Turnover Won | AA51: =Dashboard!IB4 -> 20
C52: Final 1/3 | E52: =Dashboard!FP4 -> 7 | F52: =E52/E$51 -> 0.22580645 | Y52: Blocked Shots | AA52: =Dashboard!ID4 -> 6
...

Sheet Player Report
F7: IN POSSESSION | L7: OUT OF POSSESSION | R7: POSITIONING | U7: STATS
F9: ATTACK | G9: Total | H9: + | I9: - | J9: % | L9: DEFENCE | M9: Total | N9: + | O9: - | P9: % | R9: POSITION | S9: Total | U9: Goal | W9: =GETPIVOTDATA("Sum of Goal",'Dashboard (IND)'!AV6) -> 4
F10: Passes | G10: =GETPIVOTDATA("Sum of Total Passes",'Dashboard (IND)'!$BW$6) -> 388 | H10: =GETPIVOTDATA("Sum of Completed Passes",'Dashboard (IND)'!$BV$6) -> 293 | I10: =GETPIVOTDATA("Sum of Uncompleted Passes",'Dashboard (IND)'!$BU$6) -> 95 | J10: =IFERROR(H10/G10,"-") -> 0.75515464 | L10: Defensive duel | M10: =GETPIVOTDATA("Sum of Total Defensive Duel",'Dashboard (IND)'!D6) -> 35 | N10: =GETPIVOTDATA("Sum of Successful Defensive Duel",'Dashboard (IND)'!C6) -> 11 | O10: =GETPIVOTDATA("Sum of Unsuccesful Defensive Duel",'Dashboard (IND)'!B6) -> 23 | P10: =IFERROR(N10/M10,"-") -> 0.31428571 | R10: Runs in Behind | S10: =GETPIVOTDATA("Sum of Total Runs in Behind",'Dashboard (IND)'!L6) -> 9 | U10: Assist | W10: =GETPIVOTDATA("Sum of Assist",'Dashboard (IND)'!AU6) -> 5
F11: Forward Passes | G11: =GETPIVOTDATA("Sum of Total Forward Passes",'Dashboard (IND)'!$BT$6) -> 193 | H11: =GETPIVOTDATA("Sum of Completed Forward Passes",'Dashboard (IND)'!$BS$6) -> 116 | I11: =GETPIVOTDATA("Sum of Uncompleted Forward Passes",'Dashboard (IND)'!$BR$6) -> 77 | J11: =IFERROR(H11/G11,"-") -> 0.60103627 | L11: Aerial duel | M11: =GETPIVOTDATA("Sum of Total Aerial Duel",'Dashboard (IND)'!AQ6) -> 20 | N11: =GETPIVOTDATA("Sum of Succesful Aerial Duel",'Dashboard (IND)'!AP6) -> 11 | O11: =GETPIVOTDATA("Sum of Unsuccessful Aerial Duel",'Dashboard (IND)'!AO6) -> 9 | P11: =IFERROR(N11/M11,"-") -> 0.55 | R11: Move into Pocket | S11: =GETPIVOTDATA("Sum of Total Into Pocket",'Dashboard (IND)'!H6) -> 35 | U11: Shots | W11: =GETPIVOTDATA("Sum of Total Shots",'Dashboard (IND)'!AZ6) -> 10
F12: Lateral Passes | G12: =GETPIVOTDATA("Sum of Total Lateral Passes",'Dashboard (IND)'!$BQ$6) -> 90 | H12: =GETPIVOTDATA("Sum of Completed Lateral Passes",'Dashboard (IND)'!$BP$6) -> 77 | I12: =GETPIVOTDATA("Sum of Uncompleted Lateral Passes",'Dashboard (IND)'!$BO$6) -> 13 | J12: =IFERROR(H12/G12,"-") -> 0.85555556 | L12: 1v1 Defence | M12: =GETPIVOTDATA("Sum of Total 1v1 Defence",'Dashboard (IND)'!AN6) -> 9 | N12: =GETPIVOTDATA("Sum of Successful 1v1 Defence",'Dashboard (IND)'!AM6) -> 6 | O12: =GETPIVOTDATA("Sum of Unsuccessful 1v1 Defence",'Dashboard (IND)'!AL6) -> 3 | P12: =IFERROR(N12/M12,"-") -> 0.66666667 | R12: Wide Area | S12: =GETPIVOTDATA("Sum of Total Wide Area",'Dashboard (IND)'!I6) -> 57 | U12: On target | W12: =GETPIVOTDATA("Sum of On Target",'Dashboard (IND)'!AX6) -> 4
F13: Backward Passes | G13: =GETPIVOTDATA("Sum of Total Backward Passes",'Dashboard (IND)'!$BN$6) -> 105 | H13: =GETPIVOTDATA("Sum of Completed Backward Passes",'Dashboard (IND)'!$BM$6) -> 100 | I13: =GETPIVOTDATA("Sum of Uncompleted Backward Passes",'Dashboard (IND)'!$BL$6) -> 5 | J13: =IFERROR(H13/G13,"-") -> 0.95238095 | L13: Tackles | M13: =GETPIVOTDATA("Sum of Total Tackles",'Dashboard (IND)'!AK6) -> 9 | N13: =GETPIVOTDATA("Sum of Successful Tackles",'Dashboard (IND)'!AJ6) -> 9 | O13: =GETPIVOTDATA("Sum of Unsuccessful Tackles",'Dashboard (IND)'!AI6) -> 0 | P13: =IFERROR(N13/M13,"-") -> 1 | R13: Back to Goal | S13: =GETPIVOTDATA("Sum of Total Back to Goal",'Dashboard (IND)'!J6) -> 13 | U13: Off Target | W13: =GETPIVOTDATA("Sum of Off Target",'Dashboard (IND)'!AY6) -> 3
F14: Long Passes | G14: =GETPIVOTDATA("Sum of Total Long Passes",'Dashboard (IND)'!$BK$6) -> 43 | H14: =GETPIVOTDATA("Sum of Completed Long Passes",'Dashboard (IND)'!$BJ$6) -> 20 | I14: =GETPIVOTDATA("Sum of Completed Long Passes",'Dashboard (IND)'!$BI$6) -> 20 | J14: =IFERROR(H14/G14,"-") -> 0.46511628 | L14: 2nd Ball | M14: =GETPIVOTDATA("Sum of Total 2nd Ball",'Dashboard (IND)'!AH6) -> 15 | N14: =GETPIVOTDATA("Sum of Successful 2nd Ball",'Dashboard (IND)'!AG6) -> 8 | O14: =GETPIVOTDATA("Sum of Unsuccessful 2nd Ball",'Dashboard (IND)'!AF6) -> 7 | P14: =IFERROR(N14/M14,"-") -> 0.53333333 | R14: Over/Underlaps | S14: =GETPIVOTDATA("Sum of Total Over/Underlaps",'Dashboard (IND)'!K6) -> 1 | U14: Blocked | W14: =GETPIVOTDATA("Sum of Blocked",'Dashboard (IND)'!AW6) -> 3
F15: Passes in Behind | G15: =GETPIVOTDATA("Sum of Total Balls in Behind",'Dashboard (IND)'!$BH$6) -> 23 | H15: =GETPIVOTDATA("Sum of Completed Balls in Behind",'Dashboard (IND)'!$BG$6) -> 10 | I15: =GETPIVOTDATA("Sum of Uncompleted Balls in Behind",'Dashboard (IND)'!$BF$6) -> 14 | J15: =IFERROR(H15/G15,"-") -> 0.43478261 | L15: Interception | M15: =GETPIVOTDATA("Sum of Interception",'Dashboard (IND)'!AD6) -> 26 | R15: Half-space Runs | S15: =GETPIVOTDATA("Sum of Total Half-space Runs",'Dashboard (IND)'!C6) -> 0
F16: Cross | G16: =GETPIVOTDATA("Sum of Total Cross",'Dashboard (IND)'!$AR$6) -> 12 | H16: =GETPIVOTDATA("Sum of Completed Cross",'Dashboard (IND)'!$AQ$6) -> 2 | I16: =GETPIVOTDATA("Sum of Uncompleted Cross",'Dashboard (IND)'!$AP$6) -> 10 | J16: =IFERROR(H16/G16,"-") -> 0.16666667 | L16: Clearance | M16: =GETPIVOTDATA("Sum of Clearance",'Dashboard (IND)'!AE6) -> 11 | U16: GK STATS
F17: 1v1 Attack | G17: =GETPIVOTDATA("Sum of Total 1v1",'Dashboard (IND)'!$AS$6) -> 23 | H17: =GETPIVOTDATA("Sum of Successful 1v1",'Dashboard (IND)'!AT6) -> 21 | I17: =GETPIVOTDATA("Sum of Unsuccessful 1v1",'Dashboard (IND)'!AS6) -> 2 | J17: =IFERROR(H17/G17,"-") -> 0.91304348 | L17: Recovery | M17: =GETPIVOTDATA("Sum of Recovery",'Dashboard (IND)'!AC6) -> 13 | O17: MINUTES PLAYED | R17: RECEIVING | U17: Conceded | W17: =GETPIVOTDATA("Sum of Goal Conceded",'Dashboard (IND)'!R6) -> 4
F18: Offensive Duel | G18: =GETPIVOTDATA("Sum of Total Offensive Duel",'Dashboard (IND)'!$AI$6) -> 19 | H18: =GETPIVOTDATA("Sum of Successful Offensive Duel",'Dashboard (IND)'!$AH$6) -> 17 | I18: =GETPIVOTDATA("Sum of Unsuccessful Offensive Duel",'Dashboard (IND)'!$AG$6) -> 2 | J18: =IFERROR(H18/G18,"-") -> 0.89473684 | L18: Turnover Won | M18: =GETPIVOTDATA("Sum of Turnover Won",'Dashboard (IND)'!B6) -> 20 | O18: =GETPIVOTDATA("Sum of Duration (mins)",'Dashboard (IND)'!$P$6) -> 840 | R18: Ball Received | S18: =GETPIVOTDATA("Sum of Total Pass Received",'Dashboard (IND)'!M6) -> 272 | U18: On Target | W18: =GETPIVOTDATA("Sum of GK On target",'Dashboard (IND)'!W6) -> 10
F19: Key Pass | G19: =GETPIVOTDATA("Sum of Total Through Passes",'Dashboard (IND)'!BN6) -> 7 | L19: Blocked Shots | M19: =GETPIVOTDATA("Sum of Blocked Shots",'Dashboard (IND)'!AB6) -> 6 | R19: Ball LOST | S19: =GETPIVOTDATA("Sum of Ball Lost",'Dashboard (IND)'!BK6) -> 31 | U19: Off Target | W19: =GETPIVOTDATA("Sum of GK Off Target",'Dashboard (IND)'!V6) -> 7
F20: Acceleration | G20: =GETPIVOTDATA("Sum of Total Acceleration",'Dashboard (IND)'!G6) -> 21 | L20: Fouls | M20: =GETPIVOTDATA("Sum of Fouls",'Dashboard (IND)'!Y6) -> 12 | R20: Final 1/3 | S20: =GETPIVOTDATA("Sum of Ball Lost in Final 1/3",'Dashboard (IND)'!BJ6) -> 7 | U20: Save | W20: =GETPIVOTDATA("Sum of Save",'Dashboard (IND)'!Q6) -> 3
F21: Touches in box | G21: =GETPIVOTDATA("Sum of Touches in the Box",'Dashboard (IND)'!AV6) -> 13 | L21: Won Fouls | M21: =GETPIVOTDATA("Sum of Won Fouls",'Dashboard (IND)'!Z6) -> 6 | R21: Middle 1/3 | S21: =GETPIVOTDATA("Sum of Ball Lost in Middle 1/3",'Dashboard (IND)'!BI6) -> 15 | U21: 1v1 | W21: =GETPIVOTDATA("Sum of GK 1v1",'Dashboard (IND)'!X6) -> 2
R22: Own 1/3 | S22: =GETPIVOTDATA("Sum of Ball Lost in Own 1/3",'Dashboard (IND)'!BH6) -> 9 | U22: Defend the Space | W22: =GETPIVOTDATA("Sum of Defence the Space",'Dashboard (IND)'!U6) -> 4
U23: Defence Line (Cross) | W23: =GETPIVOTDATA("Sum of Defend the line (Cross)",'Dashboard (IND)'!T6) -> 3
U24: Counter Kick | W24: =GETPIVOTDATA("Sum of Counter Kick",'Dashboard (IND)'!S6) -> 2

Sheet Dashboard
D1: DATE | E1: Team | F1: Opposition | G1: Venue | H1: Competition | I1: Formation | J1: Half | K1: Time | L1: Result | M1: Goal Scored | N1: Goal Conceded | O1: Total Play time (mins) | P1: Ball in play time (mins) | Q1: Out of play time (mins) | R1: Ball in play % | S1: Out of play % | T1: Time spent In Possession | U1: Time spen Out of Possession | V1: In Possession % | W1: Out of Possession % | X1: Number of chances | Y1: Total Number of Shots | Z1: Number of Shots on target | AA1: Number of Shots off target | AB1: Number of Shots Blocked | AC1: On target % | AD1: Off target % | AE1: Blocked % | AF1: Numer of Shots in the Box | AG1: Number of Shots from Open Play | AH1: Number of Shots by Cross | AI1: Number of Shots by Counterattack | AJ1: Number of Shots by Through Pass | AK1: Number of Shots from Transition | AL1: Number of Shots from Set play | AM1: Number of Shots from Restart | AN1: Number of Opp chances | AO1: Total Number of Opp Shots | AP1: Number of Opp Shots on target | AQ1: Number of Opp Shots off target | AR1: Number of Opp Shots Blocked | AS1: Opp on target % | AT1: Opp off target % | AU1: Opp Blocked % | AV1: Numer of Opp Shots in the Box | AW1: Number of Opp Shots from Open Play | AX1: Number of Opp Shots by Cross | AY1: Number of Opp Shots by Counterattack | AZ1: Number of Opp Shots by Through Pass | BA1: Number of Opp Shots from Transition | BB1: Number of Opp Shots from Set play | BC1: Number of Opp Shots from Restart | BD1: Number of Build the Attack | BE1: Build up + | BF1: Build up - | BG1: Build up + % | BH1: Build up - % | BI1: Number of Turnovers | BJ1: Number of Direct play | BK1: Number of Reach Opp Half | BL1: Number of Create | BM1: Create + | BN1: Create - | BO1: Create + % | BP1: Create - % | BQ1: Number of Cross | BR1: Cross + | BS1: Cross - | BT1: Succ Cross % | BU1: Unsucc Cross % | BV1: Number of Opp Cross | BW1: Opp Cross + | BX1: Opp Cross - | BY1: Opp Cross + % | BZ1: Opp Cross - % | CA1: Number of High pressing | CB1: High Pressing + | CC1: High Pressing - | CD1: Succ High Pressing % | CE1: Unsucc High Pressing % | CF1: Number of Regain Opp Half | CG1: Number of Force error | CH1: Number of Opp Direct Play | CI1: Number of Mid Block | CJ1: Mid Block + | CK1: Mid Block - | CL1: Succ Mid Block % | CM1: Unsucc Mid Block % | CN1: Number of Low Block | CO1: Low Block + | CP1: Low Block - | CQ1: Succ Low Block % | CR1: Unsucc Low Block % | CS1: Number of Transition to Attack | CT1: Number of Transition to Counterattack | CU1: Transition to Att in Final 1/3 | CV1: Transition to Att in Middle Area | CW1: Transition to Att in Own 1/3 | CX1: Number of Transition to Defense | CY1: Number of Opp Transition to Counterattack | CZ1: Transition to Def in Final 1/3 | DA1: Transition to Def in Middle Area | DB1: Transition to Def in Own 1/3 | DC1: P'Boro Corner | DD1: Opp Corner | DE1: P'Boro Throw in | DF1: P'Boro Throw in to Final 1/3 | DG1: P'Boro Throw in to Middle 1/3 | DH1: P'Boro Throw in to Own 1/3 | DI1: Opp Throw in | DJ1: Opp Throw in to Final 1/3 | DK1: Opp Throw in to Middle 1/3 | DL1: Opp Throw in to Own 1/3 | DM1: P'Boro Free Kick | DN1: P'Boro Free Kick in Final 1/3 | DO1: Opp Free Kick | DP1: Opp Free Kick in Final 1/3 | DQ1: P'Boro Goal Kick | DR1: Opp Goal kick | DS1: P'Boro Final 1/3 Entry | DT1: P'Boro In Play Final 1/3 Entry | DU1: Opp Final 1/3 Entry | DV1: Opp in play Final 1/3 Entry | DW1: Final 1/3 Entry | DX1: P'Boro Touches in the Box | DY1: Opponent Touches in the Box | DZ1: Touches in the Box | EA1: Total Passes | EB1: Total Completed Passes | EC1: Total Uncompleted Passes | ED1: Total Completed Passes % | EE1: Total Uncompleted Passes % | EF1: Total Forward Pases | EG1: Total Completed Forward Passes | EH1: Total Uncompleted Forward Passes | EI1: Total Completed Forward Passes % | EJ1: Total Uncompleted Forward Passes % | EK1: Total Lateral Passes | EL1: Total Completed Lateral Passes | EM1: Total Uncompleted Lateral Passes | EN1: Total Completed Lateral Passes % | EO1: Total Uncompleted Lateral Passes % | EP1: Total Backward Passes | EQ1: Total Completed Backward Passes | ER1: Total Uncompleted Backward Passes | ES1: Total Completed Backward Passes % | ET1: Total Uncompleted Backward Passes % | EU1: Total Long Passes | EV1: Total Completed Long Passes | EW1: Total Uncompleted Long Passes | EX1: Total Completed Long Passes % | EY1: Total Uncompleted Long Passes % | EZ1: Total Balls in Behind | FA1: Total Completed Balls in Behind | FB1: Total Uncompleted Balls in Behind | FC1: Total Completed Balls in Behind % | FD1: Total Uncompleted Balls in Behind % | FE1: Total Through Passes | FF1: Total Diagonal Passes | FG1: Total Completed Diagonal Passes | FH1: Total Uncompleted Diagonal Passes | FI1: Total Completed Diagonal Passes % | FJ1: Total Uncompleted Diagonal Passes % | FK1: Total Pass Received | FL1: Total Pass Received & Pass completed | FM1: Total Pass Received & Pass Uncompleted | FN1: Total Ball Kept | FO1: Total Ball Lost | FP1: Total Lost balls in Final 1/3 | FQ1: Total Lost balls in Middle 1/3 | FR1: Total Lost balls in Own 1/3 | FS1: Total Touches in the Box | FT1: Total 1v1 | FU1: Total Successful 1v1 | FV1: Total Unsuccessful 1v1 | FW1: Total Completed 1v1 % | FX1: Total Uncompleted 1v1 % | FY1: Total cross | FZ1: Total Completed Cross | GA1: Total Uncompleted Cross | GB1: Total Completed Cross % | GC1: Total Uncompleted Cross % | GD1: Total Shots | GE1: Total On Target | GF1: Total Off Target | GG1: Total Blocked | GH1: Total Goal | GI1: Total Assist | GJ1: Total Offensive Duel | GK1: Total Succ Offensive duel | GL1: Total Unsuc Offensive duel | GM1: Total Succ Offensive duel % | GN1: Total Unsuc Offensive duel % | GO1: Total Acceleration | GP1: Total into Pocket | GQ1: Total Wide Area | GR1: Total Back to Goal | GS1: Total Over/Underlaps | GT1: Total Runs in Behind | GU1: Total Half-space Runs | GV1: Total Duel | GW1: Succ Duel | GX1: Unsucc Duel | GY1: Succ Duel % | GZ1: Unsucc Duel % | HA1: Total Defensive Duel | HB1: Total Succ Defensive duel | HC1: Total Unsuc Defensive duel | HD1: Total Succ Defensive duel % | HE1: Total Unsuc Defensive duel % | HF1: Total Aerial duel | HG1: Total Succ Aerial duel | HH1: Total Unsuc Aerial duel | HI1: Total Succ Aerial duel % | HJ1: Total Unsuc Aerial duel % | HK1: Total 1v1 Defence | HL1: Total Succ 1v1 Defence | HM1: Total Unsuc 1v1 Defence | HN1: Total Succ 1v1 Defence % | HO1: Total Unsuc 1v1 Defence % | HP1: Total Tackles | HQ1: Total Succ Tackles | HR1: Total Unsuc Tackles | HS1: Total Succ Tackles % | HT1: Total Unsuc Tackles % | HU1: Total 2nd Ball | HV1: Total Succ 2nd Ball | HW1: Total Unsuc 2nd Ball | HX1: Total Succ 2nd Ball % | HY1: Total Unsuc 2nd Ball % | HZ1: Total Clearance | IA1: Total Interception | IB1: Turnover Won | IC1: Total Recovery | ID1: Total Blockd Shots | IE1: Total Missed Man-marking | IF1: Total Fouls | IG1: Total Won Fouls | IH1: GK 1v1 | II1: GK On target | IJ1: GK Off Target | IK1: Defence the Space | IL1: Goal Conceded | IM1: Save | IN1: Defend the line (Cross) | IO1: Counter Kick
E2: Peterborough | F2: Onside Academy | G2: H | H2: Preseason | I2: 1-4-3-3 | J2: 1st Half | K2: 1st Half | L2: {=_xlfn.IFS(M2<N2,"L",M2=N2,"D",M2>N2,"W")} -> D | M2: =COUNTIFS('Raw data'!$Y:$Y,"*1st*",'Raw data'!$D:$D,"P'Boro Goal") -> 2 | N2: =COUNTIFS('Raw data'!$Y:$Y,"*1st*",'Raw data'!$D:$D,"Opp Goal") -> 2 | O2: =P2+Q2 -> 45.446166 | P2: =SUMIFS('Raw data'!$C:$C,'Raw data'!$D:$D,"Ball in play",'Raw data'!$Y:$Y,"*1st*") /60 -> 24.820005 | Q2: =SUMIFS('Raw data'!$C:$C,'Raw data'!$D:$D,"Out of play",'Raw data'!$Y:$Y,"*1st*") /60 -> 20.626161 | R2: =P2/O2 -> 0.54614079 | S2: =Q2/O2 -> 0.45385921 | T2: =(SUMIFS('Raw data'!$C:$C,'Raw data'!$D:$D,"In Possession",'Raw data'!$Y:$Y,"*1st*")-(3*(COUNTIFS('Raw data'!$D:$D,"In Possession",'Raw data'!$Y:$Y,"*1st*"))))/60 -> 16.94571 | U2: =(SUMIFS('Raw data'!$C:$C,'Raw data'!$D:$D,"Out of Possession",'Raw data'!$Y:$Y,"*1st*")-(3*(COUNTIFS('Raw data'!$D:$D,"Out of Possession",'Raw data'!$Y:$Y,"*1st*"))))/60 -> 8.3841511 | V2: =T2/(T2+U2) -> 0.6690013 | W2: =U2/(T2+U2) -> 0.3309987 | X2: =COUNTIFS('Raw data'!$D:$D,"P'Boro Chance",'Raw data'!$Y:$Y,"*1st*") -> 6 | Y2: =SUM(Z2:AB2) -> 6 | Z2: =COUNTIFS('Raw data'!$D:$D,"P'Boro Chance",'Raw data'!$Q:$Q,"*On Target*",'Raw data'!$Y:$Y,"*1st*") -> 2 | AA2: =COUNTIFS('Raw data'!$D:$D,"P'Boro Chance",'Raw data'!$Q:$Q,"*Off Target*",'Raw data'!$Y:$Y,"*1st*") -> 1 | AB2: =COUNTIFS('Raw data'!$D:$D,"P'Boro Chance",'Raw data'!$Q:$Q,"*Blocked*",'Raw data'!$Y:$Y,"*1st*") -> 3 | AC2: =Z2/Y2 -> 0.33333333 | AD2: =AA2/Y2 -> 0.16666667 | AE2: =AB2/Y2 -> 0.5 | AF2: =COUNTIFS('Raw data'!$D:$D,"P'Boro Chance",'Raw data'!$Q:$Q,"*Shots in the box*",'Raw data'!$Y:$Y,"*1st*") -> 4 | AG2: =COUNTIFS('Raw data'!$D:$D,"P'Boro Chance",'Raw data'!$Q:$Q,"*Shots from Open Play*",'Raw data'!$Y:$Y,"*1st*") -> 3 | AH2: =COUNTIFS('Raw data'!$D:$D,"P'Boro Chance",'Raw data'!$Q:$Q,"*Cross to Shots*",'Raw data'!$Y:$Y,"*1st*") -> 1 | AI2: =COUNTIFS('Raw data'!$D:$D,"P'Boro Chance",'Raw data'!$Q:$Q,"*Counterattack to Shots*",'Raw data'!$Y:$Y,"*1st*") -> 2 | AJ2: =COUNTIFS('Raw data'!$D:$D,"P'Boro Chance",'Raw data'!$Q:$Q,"*Through Pass to Shots*",'Raw data'!$Y:$Y,"*1st*") -> 2 | AK2: =COUNTIFS('Raw data'!$D:$D,"P'Boro Chance",'Raw data'!$Q:$Q,"*Shots from Transition*",'Raw data'!$Y:$Y,"*1st*") -> 3 | AL2: =COUNTIFS('Raw data'!$D:$D,"P'Boro Chance",'Raw data'!$Q:$Q,"*Shots from Set Play*",'Raw data'!$Y:$Y,"*1st*") -> 0 | AM2: =COUNTIFS('Raw data'!$D:$D,"P'Boro Chance",'Raw data'!$Q:$Q,"*Shots from Restart*",'Raw data'!$Y:$Y,"*1st*") -> 0 | AN2: =COUNTIFS('Raw data'!$D:$D,"Opp Chance",'Raw data'!$Y:$Y,"*1st*") -> 12 | AO2: =SUM(AP2:AR2) -> 11 | AP2: =COUNTIFS('Raw data'!$D:$D,"Opp Chance",'Raw data'!$Q:$Q,"*On Target*",'Raw data'!$Y:$Y,"*1st*") -> 4 | AQ2: =COUNTIFS('Raw data'!$D:$D,"Opp Chance",'Raw data'!$Q:$Q,"*Off Target*",'Raw data'!$Y:$Y,"*1st*") -> 6 | AR2: =COUNTIFS('Raw data'!$D:$D,"Opp Chance",'Raw data'!$Q:$Q,"*Blocked*",'Raw data'!$Y:$Y,"*1st*") -> 1 | AS2: =AP2/AO2 -> 0.36363636 | AT2: =AQ2/AO2 -> 0.54545455 | AU2: =AR2/AO2 -> 0.090909091 | AV2: =COUNTIFS('Raw data'!$D:$D,"Opp Chance",'Raw data'!$Q:$Q,"*Shots in the box*",'Raw data'!$Y:$Y,"*1st*") -> 4 | AW2: =COUNTIFS('Raw data'!$D:$D,"Opp Chance",'Raw data'!$Q:$Q,"*Shots from Open Play*",'Raw data'!$Y:$Y,"*1st*") -> 0 | AX2: =COUNTIFS('Raw data'!$D:$D,"Opp Chance",'Raw data'!$Q:$Q,"*Cross to Shots*",'Raw data'!$Y:$Y,"*1st*") -> 1 | AY2: =COUNTIFS('Raw data'!$D:$D,"Opp Chance",'Raw data'!$Q:$Q,"*Counterattack to Shots*",'Raw data'!$Y:$Y,"*1st*") -> 1 | AZ2: =COUNTIFS('Raw data'!$D:$D,"Opp Chance",'Raw data'!$Q:$Q,"*Through Pass to Shots*",'Raw data'!$Y:$Y,"*1st*") -> 2 | BA2: =COUNTIFS('Raw data'!$D:$D,"Opp Chance",'Raw data'!$Q:$Q,"*Shots from Transition*",'Raw data'!$Y:$Y,"*1st*") -> 9 | BB2: =COUNTIFS('Raw data'!$D:$D,"Opp Chance",'Raw data'!$Q:$Q,"*Shots from Set Play*",'Raw data'!$Y:$Y,"*1st*") -> 1 | BC2: =COUNTIFS('Raw data'!$D:$D,"Opp Chance",'Raw data'!$Q:$Q,"*Shots from Restart*",'Raw data'!$Y:$Y,"*1st*") -> 2 | BD2: =COUNTIFS('Raw data'!$D:$D,"Build the Attack",'Raw data'!$Y:$Y,"*1st*") -> 28 | BE2: =COUNTIFS('Raw data'!$D:$D,"Build the Attack",'Raw data'!$R:$R,"*+*",'Raw data'!$Y:$Y,"*1st*") -> 10 | BF2: =COUNTIFS('Raw data'!$D:$D,"Build the Attack",'Raw data'!$R:$R,"-",'Raw data'!$Y:$Y,"*1st*") -> 18 | BG2: =BE2/BD2 -> 0.35714286 | BH2: =BF2/BD2 -> 0.64285714 | BI2: =COUNTIFS('Raw data'!$D:$D,"Build the Attack",'Raw data'!$P:$P,"*Turnover*",'Raw data'!$Y:$Y,"*1st*") -> 7 | BJ2: =COUNTIFS('Raw data'!$D:$D,"Build the Attack",'Raw data'!$P:$P,"*Direct play*",'Raw data'!$Y:$Y,"*1st*") -> 9 | BK2: =COUNTIFS('Raw data'!$D:$D,"Build the Attack",'Raw data'!$P:$P,"*Reach Opp Half*",'Raw data'!$Y:$Y,"*1st*") -> 6 | BL2: =COUNTIFS('Raw data'!$D:$D,"Create the Attack",'Raw data'!$Y:$Y,"*1st*") -> 21 | BM2: =COUNTIFS('Raw data'!$D:$D,"Create the Attack",'Raw data'!$R:$R,"+",'Raw data'!$Y:$Y,"*1st*") -> 7 | BN2: =COUNTIFS('Raw data'!$D:$D,"Create the Attack",'Raw data'!$R:$R,"-",'Raw data'!$Y:$Y,"*1st*") -> 14 | BO2: =BM2/BL2 -> 0.33333333 | BP2: =BN2/BL2 -> 0.66666667 | BQ2: =COUNTIFS('Raw data'!$D:$D,"P'Boro Cross",'Raw data'!$Y:$Y,"*1st*") -> 6 | BR2: =COUNTIFS('Raw data'!$D:$D,"P'Boro Cross",'Raw data'!$R:$R,"+",'Raw data'!$Y:$Y,"*1st*") -> 2 | BS2: =COUNTIFS('Raw data'!$D:$D,"P'Boro Cross",'Raw data'!$R:$R,"-",'Raw data'!$Y:$Y,"*1st*") -> 4 | BT2: =BR2/BQ2 -> 0.33333333 | BU2: =BS2/BQ2 -> 0.66666667 | BV2: =COUNTIFS('Raw data'!$D:$D,"Opp Cross",'Raw data'!$Y:$Y,"*1st*") -> 4 | BW2: =COUNTIFS('Raw data'!$D:$D,"Opp Cross",'Raw data'!$R:$R,"+",'Raw data'!$Y:$Y,"*1st*") -> 1 | BX2: =COUNTIFS('Raw data'!$D:$D,"Opp Cross",'Raw data'!$R:$R,"-",'Raw data'!$Y:$Y,"*1st*") -> 3 | BY2: =BW2/BV2 -> 0.25 | BZ2: =BX2/BV2 -> 0.75 | CA2: =COUNTIFS('Raw data'!$D:$D,"High Block",'Raw data'!$Y:$Y,"*1st*") -> 1 | CB2: =COUNTIFS('Raw data'!$D:$D,"High Block",'Raw data'!$R:$R,"+",'Raw data'!$Y:$Y,"*1st*") -> 1 | CC2: =COUNTIFS('Raw data'!$D:$D,"High Block",'Raw data'!$R:$R,"-",'Raw data'!$Y:$Y,"*1st*") -> 0 | CD2: =CB2/CA2 -> 1 | CE2: =CC2/CA2 -> 0 | CF2: =COUNTIFS('Raw data'!$D:$D,"High Block",'Raw data'!$S:$S,"Regain Opp Half",'Raw data'!$Y:$Y,"*1st*") -> 0 | CG2: =COUNTIFS('Raw data'!$D:$D,"High Block",'Raw data'!$S:$S,"Force error",'Raw data'!$Y:$Y,"*1st*") -> 1 | CH2: =COUNTIFS('Raw data'!$D:$D,"High Block",'Raw data'!$P:$P,"Direct play",'Raw data'!$Y:$Y,"*1st*") -> 0 | CI2: =COUNTIFS('Raw data'!$D:$D,"Mid Block",'Raw data'!$Y:$Y,"*1st*") -> 0 | CJ2: =COUNTIFS('Raw data'!$D:$D,"Mid Block",'Raw data'!$R:$R,"+",'Raw data'!$Y:$Y,"*1st*") -> 0 | CK2: =COUNTIFS('Raw data'!$D:$D,"Mid Block",'Raw data'!$R:$R,"-",'Raw data'!$Y:$Y,"*1st*") -> 0 | CL2: =CJ2/CI2 -> #DIV/0! | CM2: =CK2/CI2 -> #DIV/0! | CN2: =COUNTIFS('Raw data'!$D:$D,"Low Block",'Raw data'!$Y:$Y,"*1st*") -> 0 | CO2: =COUNTIFS('Raw data'!$D:$D,"Low Block",'Raw data'!$R:$R,"+",'Raw data'!$Y:$Y,"*1st*") -> 0 | CP2: =COUNTIFS('Raw data'!$D:$D,"Low Block",'Raw data'!$R:$R,"-",'Raw data'!$Y:$Y,"*1st*") -> 0 | CQ2: =CO2/CN2 -> #DIV/0! | CR2: =CP2/CN2 -> #DIV/0! | CS2: =SUM(CU2:CW2) -> 30 | CT2: =COUNTIFS('Raw data'!$D:$D,"Transition to Attack",'Raw data'!$U:$U,"*Transition to Att Counter*",'Raw data'!$Y:$Y,"*1st*") -> 3 | CU2: =COUNTIFS('Raw data'!$D:$D,"Transition to Attack",'Raw data'!$U:$U,"*Final 1/3*",'Raw data'!$Y:$Y,"*1st*") -> 0 | CV2: =COUNTIFS('Raw data'!$D:$D,"Transition to Attack",'Raw data'!$U:$U,"*Middle 1/3*",'Raw data'!$Y:$Y,"*1st*") -> 17 | CW2: =COUNTIFS('Raw data'!$D:$D,"Transition to Attack",'Raw data'!$U:$U,"*Own 1/3*",'Raw data'!$Y:$Y,"*1st*") -> 13 | CX2: =SUM(CZ2:DB2) -> 36 | CY2: =COUNTIFS('Raw data'!$D:$D,"Transition to Defense",'Raw data'!$U:$U,"*Transition to def counter*",'Raw data'!$Y:$Y,"*1st*") -> 1 | CZ2: =COUNTIFS('Raw data'!$D:$D,"Transition to Defense",'Raw data'!$U:$U,"*Final 1/3*",'Raw data'!$Y:$Y,"*1st*") -> 12 | DA2: =COUNTIFS('Raw data'!$D:$D,"Transition to Defense",'Raw data'!$U:$U,"*Middle 1/3*",'Raw data'!$Y:$Y,"*1st*") -> 14 | DB2: =COUNTIFS('Raw data'!$D:$D,"Transition to Defense",'Raw data'!$U:$U,"*Own 1/3*",'Raw data'!$Y:$Y,"*1st*") -> 10 | DC2: =COUNTIFS('Raw data'!$T:$T,"P'Boro Corner",'Raw data'!$Y:$Y,"*1st*") -> 0 | DD2: =COUNTIFS('Raw data'!$T:$T,"Opp Corner",'Raw data'!$Y:$Y,"*1st*") -> 2 | DE2: =COUNTIFS('Raw data'!$T:$T,"*P'Boro Throw in*",'Raw data'!$Y:$Y,"*1st*") -> 7 | DF2: =COUNTIFS('Raw data'!$T:$T,"*P'Boro Throw in*",'Raw data'!$U:$U,"*Final 1/3*",'Raw data'!$Y:$Y,"*1st*") -> 4 | DG2: =COUNTIFS('Raw data'!$T:$T,"*P'Boro Throw in*",'Raw data'!$U:$U,"*Middle 1/3*",'Raw data'!$Y:$Y,"*1st*") -> 1 | DH2: =COUNTIFS('Raw data'!$T:$T,"*P'Boro Throw in*",'Raw data'!$U:$U,"*Own 1/3*",'Raw data'!$Y:$Y,"*1st*") -> 2 | DI2: =COUNTIFS('Raw data'!$T:$T,"*Opp Throw in*",'Raw data'!$Y:$Y,"*1st*") -> 11 | DJ2: =COUNTIFS('Raw data'!$T:$T,"*Opp Throw in*",'Raw data'!$U:$U,"*Own 1/3*",'Raw data'!$Y:$Y,"*1st*") -> 4 | DK2: =COUNTIFS('Raw data'!$T:$T,"*Opp Throw in*",'Raw data'!$U:$U,"*Middle 1/3*",'Raw data'!$Y:$Y,"*1st*") -> 1 | DL2: =COUNTIFS('Raw data'!$T:$T,"*Opp Throw in*",'Raw data'!$U:$U,"*Own 1/3*",'Raw data'!$Y:$Y,"*1st*") -> 4 | DM2: =COUNTIFS('Raw data'!$T:$T,"P'Boro Free Kick",'Raw data'!$Y:$Y,"*1st*") -> 5 | DN2: =COUNTIFS('Raw data'!$T:$T,"P'Boro Free kick",'Raw data'!$U:$U,"Final 1/3",'Raw data'!$Y:$Y,"*1st*") -> 0 | DO2: =COUNTIFS('Raw data'!$T:$T,"Opp Free Kick",'Raw data'!$Y:$Y,"*1st*") -> 4 | DP2: =COUNTIFS('Raw data'!$T:$T,"Opp Free kick",'Raw data'!$U:$U,"Final 1/3",'Raw data'!$Y:$Y,"*1st*") -> 0 | DQ2: =COUNTIFS('Raw data'!$T:$T,"P'Boro Goal Kick",'Raw data'!$Y:$Y,"*1st*") -> 11 | DR2: =COUNTIFS('Raw data'!$T:$T,"Opp Goal Kick",'Raw data'!$Y:$Y,"*1st*") -> 5 | DS2: =SUM(DT2,DF2,CU2) -> 19 | DT2: =COUNTIFS('Raw data'!$D:$D,"P'Boro 1/3 Entry",'Raw data'!$Y:$Y,"*1st*") -> 15 | DU2: =SUM(DJ2,DV2,DB2) -> 23 | DV2: =COUNTIFS('Raw data'!$D:$D,"Opp 1/3 Entry",'Raw data'!$Y:$Y,"*1st*") -> 9 | DW2: =SUM(DS2,DU2) -> 42 | DX2: =COUNTIFS('Raw data'!$D:$D,"P'Boro Touches in Box",'Raw data'!$Y:$Y,"*1st*") -> 7 | DY2: =COUNTIFS('Raw data'!$D:$D,"Opp Touches in Box",'Raw data'!$Y:$Y,"*1st*") -> 7 | DZ2: =SUM(DX2:DY2) -> 14 | EA2: =SUM(EA13:EA23) -> 213 | EB2: =SUM(EB13:EB23) -> 155 | EC2: =SUM(EC13:EC23) -> 58 | ED2: =IFERROR(EB2/EA2,"-") -> 0.72769953 | EE2: =IFERROR(EC2/EA2,"-") -> 0.27230047 | EF2: =SUM(EF13:EF23) -> 102 | EG2: =SUM(EG13:EG23) -> 55 | EH2: =SUM(EH13:EH23) -> 47 | EI2: =IFERROR(EG2/EF2,"-") -> 0.53921569 | EJ2: =IFERROR(EH2/EF2,"-") -> 0.46078431 | EK2: =SUM(EK13:EK23) -> 56 | EL2: =SUM(EL13:EL23) -> 49 | EM2: =SUM(EM13:EM23) -> 7 | EN2: =IFERROR(EL2/EK2,"-") -> 0.875 | EO2: =IFERROR(EM2/EK2,"-") -> 0.125 | EP2: =SUM(EP13:EP23) -> 55 | EQ2: =SUM(EQ13:EQ23) -> 51 | ER2: =SUM(ER13:ER23) -> 4 | ES2: =IFERROR(EQ2/EP2,"-") -> 0.92727273 | ET2: =IFERROR(ER2/EP2,"-") -> 0.072727273 | EU2: =SUM(EU13:EU23) -> 22 | EV2: =SUM(EV13:EV23) -> 8 | EW2: =SUM(EW13:EW23) -> 15 | EX2: =IFERROR(EV2/EU2,"-") -> 0.36363636 | EY2: =IFERROR(EW2/EU2,"-") -> 0.68181818 | EZ2: =SUM(EZ13:EZ23) -> 14 | FA2: =SUM(FA13:FA23) -> 7 | FB2: =SUM(FB13:FB23) -> 8 | FC2: =IFERROR(FA2/EZ2,"-") -> 0.5 | FD2: =IFERROR(FB2/EZ2,"-") -> 0.57142857 | FE2: =SUM(FE13:FE23) -> 4 | FF2: =SUM(FF13:FF23) -> 0 | FG2: =SUM(FG13:FG23) -> 0 | FH2: =SUM(FH13:FH23) -> 0 | FI2: =IFERROR(FG2/FF2,"-") -> - | FJ2: =IFERROR(FH2/FF2,"-") -> - | FK2: =SUM(FK13:FK23) -> 139 | FL2: =SUM(FL13:FL23) -> 93 | FM2: =SUM(FM13:FM23) -> 38 | FN2: =SUM(FN13:FN23) -> 11 | FO2: =SUM(FO13:FO23) -> 11 | FP2: =SUM(FP13:FP23) -> 3 | FQ2: =SUM(FQ13:FQ23) -> 5 | FR2: =SUM(FR13:FR23) -> 3 | ... FV2: =SUM(FV13:FV23) -> 0 | FW2: =IFERROR(FU2/FT2,"-") -> 1 | FX2: =IFERROR(FV2/FT2,"-") -> 0 | FY2: =SUM(FY13:FY23) -> 7 | FZ2: =SUM(FZ13:FZ23) -> 1 | GA2: =SUM(GA13:GA23) -> 6 | GB2: =IFERROR(FZ2/FY2,"-") -> 0.14285714 | GC2: =IFERROR(GA2/FY2,"-") -> 0.85714286 | GD2: =SUM(GD13:GD23) -> 6 | GE2: =SUM(GE13:GE23) -> 2 | GF2: =SUM(GF13:GF23) -> 1 | GG2: =SUM(GG13:GG23) -> 3 | GH2: =SUM(GH13:GH23) -> 2 | GI2: =SUM(GI13:GI23) -> 3 | GJ2: =SUM(GJ13:GJ23) -> 8 | GK2: =SUM(GK13:GK23) -> 8 | GL2: =SUM(GL13:GL23) -> 0 | GM2: =IFERROR(GK2/GJ2,"-") -> 1 | GN2: =IFERROR(GL2/GJ2,"-") -> 0 | GO2: =SUM(GO13:GO23) -> 12 | GP2: =SUM(GP13:GP23) -> 20 | GQ2: =SUM(GQ13:GQ23) -> 31 | GR2: =SUM(GR13:GR23) -> 5 | GS2: =SUM(GS13:GS23) -> 1 | GT2: =SUM(GT13:GT23) -> 6 | GU2: =SUM(GU13:GU23) -> 0 | GV2: =SUM(GV13:GV23) -> 32 | ... GX2: =SUM(GX13:GX23) -> 13 | GY2: =IFERROR(GW2/GV2,"-") -> 0.59375 | GZ2: =IFERROR(GX2/GV2,"-") -> 0.40625 | HA2: =SUM(HA13:HA23) -> 12 | HB2: =SUM(HB13:HB23) -> 6 | HC2: =SUM(HC13:HC23) -> 6 | HD2: =IFERROR(HB2/HA2,"-") -> 0.5 | HE2: =IFERROR(HC2/HA2,"-") -> 0.5 | HF2: =SUM(HF13:HF23) -> 12 | HG2: =SUM(HG13:HG23) -> 5 | HH2: =SUM(HH13:HH23) -> 7 | HI2: =IFERROR(HG2/HF2,"-") -> 0.41666667 | HJ2: =IFERROR(HH2/HF2,"-") -> 0.58333333 | HK2: =SUM(HK13:HK23) -> 4 | HL2: =SUM(HL13:HL23) -> 3 | HM2: =SUM(HM13:HM23) -> 1 | HN2: =IFERROR(HL2/HK2,"-") -> 0.75 | HO2: =IFERROR(HM2/HK2,"-") -> 0.25 | HP2: =SUM(HP13:HP23) -> 5 | HQ2: =SUM(HQ13:HQ23) -> 5 | HR2: =SUM(HR13:HR23) -> 0 | HS2: =IFERROR(HQ2/HP2,"-") -> 1 | HT2: =IFERROR(HR2/HP2,"-") -> 0 | HU2: =SUM(HU13:HU23) -> 10 | HV2: =SUM(HV13:HV23) -> 6 | HW2: =SUM(HW13:HW23) -> 4 | HX2: =IFERROR(HV2/HU2,"-") -> 0.6 | HY2: =IFERROR(HW2/HU2,"-") -> 0.4 | HZ2: =SUM(HZ13:HZ23) -> 5 | IA2: =SUM(IA13:IA23) -> 12 | IB2: =SUM(IB13:IB23) -> 11 | IC2: =SUM(IC13:IC23) -> 8 | ID2: =SUM(ID13:ID23) -> 2 | IE2: =SUM(IE13:IE23) -> 0 | IF2: =SUM(IF13:IF23) -> 5 | IG2: =SUM(IG13:IG23) -> 3 | ... IO2: =SUM(IO13:IO23) -> 1
E3: Peterborough | F3: Onside Academy | G3: H | H3: Preseason | I3: 1-4-3-3 | J3: 2nd Half | K3: 2nd Half | L3: {=_xlfn.IFS(M3<N3,"L",M3=N3,"D",M3>N3,"W")} -> D | M3: =COUNTIFS('Raw data'!$Y:$Y,"*2nd*",'Raw data'!$D:$D,"P'Boro Goal") -> 2 | N3: =COUNTIFS('Raw data'!$Y:$Y,"*2nd*",'Raw data'!$D:$D,"Opp Goal") -> 2 | O3: =P3+Q3 -> 40.597097 | P3: =SUMIFS('Raw data'!$C:$C,'Raw data'!$D:$D,"Ball in play",'Raw data'!$Y:$Y,"*2nd*") /60 -> 26.522591 | Q3: =SUMIFS('Raw data'!$C:$C,'Raw data'!$D:$D,"Out of play",'Raw data'!$Y:$Y,"*2nd*") /60 -> 14.074507 | R3: =P3/O3 -> 0.65331249 | S3: =Q3/O3 -> 0.34668751 | T3: =(SUMIFS('Raw data'!$C:$C,'Raw data'!$D:$D,"In Possession",'Raw data'!$Y:$Y,"*2nd*")-(3*(COUNTIFS('Raw data'!$D:$D,"In Possession",'Raw data'!$Y:$Y,"*2nd*"))))/60 -> 14.392849 | U3: =(SUMIFS('Raw data'!$C:$C,'Raw data'!$D:$D,"Out of Possession",'Raw data'!$Y:$Y,"*2nd*")-(3*(COUNTIFS('Raw data'!$D:$D,"Out of Possession",'Raw data'!$Y:$Y,"*2nd*"))))/60 -> 12.129741 | V3: =T3/(T3+U3) -> 0.54266378 | W3: =U3/(T3+U3) -> 0.45733622 | X3: =COUNTIFS('Raw data'!$D:$D,"P'Boro Chance",'Raw data'!$Y:$Y,"*2nd*") -> 6 | Y3: =SUM(Z3:AB3) -> 5 | Z3: =COUNTIFS('Raw data'!$D:$D,"P'Boro Chance",'Raw data'!$Q:$Q,"*On Target*",'Raw data'!$Y:$Y,"*2nd*") -> 3 | AA3: =COUNTIFS('Raw data'!$D:$D,"P'Boro Chance",'Raw data'!$Q:$Q,"*Off Target*",'Raw data'!$Y:$Y,"*2nd*") -> 2 | AB3: =COUNTIFS('Raw data'!$D:$D,"P'Boro Chance",'Raw data'!$Q:$Q,"*Blocked*",'Raw data'!$Y:$Y,"*2nd*") -> 0 | AC3: =Z3/Y3 -> 0.6 | AD3: =AA3/Y3 -> 0.4 | AE3: =AB3/Y3 -> 0 | AF3: =COUNTIFS('Raw data'!$D:$D,"P'Boro Chance",'Raw data'!$Q:$Q,"*Shots in the box*",'Raw data'!$Y:$Y,"*2nd*") -> 4 | AG3: =COUNTIFS('Raw data'!$D:$D,"P'Boro Chance",'Raw data'!$Q:$Q,"*Shots from Open Play*",'Raw data'!$Y:$Y,"*2nd*") -> 1 | AH3: =COUNTIFS('Raw data'!$D:$D,"P'Boro Chance",'Raw data'!$Q:$Q,"*Cross to Shots*",'Raw data'!$Y:$Y,"*2nd*") -> 1 | AI3: =COUNTIFS('Raw data'!$D:$D,"P'Boro Chance",'Raw data'!$Q:$Q,"*Counterattack to Shots*",'Raw data'!$Y:$Y,"*2nd*") -> 1 | AJ3: =COUNTIFS('Raw data'!$D:$D,"P'Boro Chance",'Raw data'!$Q:$Q,"*Through Pass to Shots*",'Raw data'!$Y:$Y,"*2nd*") -> 1 | AK3: =COUNTIFS('Raw data'!$D:$D,"P'Boro Chance",'Raw data'!$Q:$Q,"*Shots from Transition*",'Raw data'!$Y:$Y,"*2nd*") -> 2 | AL3: =COUNTIFS('Raw data'!$D:$D,"P'Boro Chance",'Raw data'!$Q:$Q,"*Shots from Set Play*",'Raw data'!$Y:$Y,"*2nd*") -> 1 | AM3: =COUNTIFS('Raw data'!$D:$D,"P'Boro Chance",'Raw data'!$Q:$Q,"*Shots from Restart*",'Raw data'!$Y:$Y,"*2nd*") -> 2 | AN3: =COUNTIFS('Raw data'!$D:$D,"Opp Chance",'Raw data'!$Y:$Y,"*2nd*") -> 13 | AO3: =SUM(AP3:AR3) -> 12 | AP3: =COUNTIFS('Raw data'!$D:$D,"Opp Chance",'Raw data'!$Q:$Q,"*On Target*",'Raw data'!$Y:$Y,"*2nd*") -> 6 | AQ3: =COUNTIFS('Raw data'!$D:$D,"Opp Chance",'Raw data'!$Q:$Q,"*Off Target*",'Raw data'!$Y:$Y,"*2nd*") -> 4 | AR3: =COUNTIFS('Raw data'!$D:$D,"Opp Chance",'Raw data'!$Q:$Q,"*Blocked*",'Raw data'!$Y:$Y,"*2nd*") -> 2 | AS3: =AP3/AO3 -> 0.5 | AT3: =AQ3/AO3 -> 0.33333333 | AU3: =AR3/AO3 -> 0.16666667 | AV3: =COUNTIFS('Raw data'!$D:$D,"Opp Chance",'Raw data'!$Q:$Q,"*Shots in the box*",'Raw data'!$Y:$Y,"*2nd*") -> 8 | AW3: =COUNTIFS('Raw data'!$D:$D,"Opp Chance",'Raw data'!$Q:$Q,"*Shots from Open Play*",'Raw data'!$Y:$Y,"*2nd*") -> 4 | AX3: =COUNTIFS('Raw data'!$D:$D,"Opp Chance",'Raw data'!$Q:$Q,"*Cross to Shots*",'Raw data'!$Y:$Y,"*2nd*") -> 3 | AY3: =COUNTIFS('Raw data'!$D:$D,"Opp Chance",'Raw data'!$Q:$Q,"*Counterattack to Shots*",'Raw data'!$Y:$Y,"*2nd*") -> 1 | AZ3: =COUNTIFS('Raw data'!$D:$D,"Opp Chance",'Raw data'!$Q:$Q,"*Through Pass to Shots*",'Raw data'!$Y:$Y,"*2nd*") -> 1 | BA3: =COUNTIFS('Raw data'!$D:$D,"Opp Chance",'Raw data'!$Q:$Q,"*Shots from Transition*",'Raw data'!$Y:$Y,"*2nd*") -> 8 | BB3: =COUNTIFS('Raw data'!$D:$D,"Opp Chance",'Raw data'!$Q:$Q,"*Shots from Set Play*",'Raw data'!$Y:$Y,"*2nd*") -> 1 | BC3: =COUNTIFS('Raw data'!$D:$D,"Opp Chance",'Raw data'!$Q:$Q,"*Shots from Restart*",'Raw data'!$Y:$Y,"*2nd*") -> 0 | BD3: =COUNTIFS('Raw data'!$D:$D,"Build the Attack",'Raw data'!$Y:$Y,"*2nd*") -> 19 | BE3: =COUNTIFS('Raw data'!$D:$D,"Build the Attack",'Raw data'!$R:$R,"*+*",'Raw data'!$Y:$Y,"*2nd*") -> 8 | BF3: =COUNTIFS('Raw data'!$D:$D,"Build the Attack",'Raw data'!$R:$R,"-",'Raw data'!$Y:$Y,"*2nd*") -> 11 | BG3: =BE3/BD3 -> 0.42105263 | BH3: =BF3/BD3 -> 0.57894737 | BI3: =COUNTIFS('Raw data'!$D:$D,"Build the Attack",'Raw data'!$P:$P,"*Turnover*",'Raw data'!$Y:$Y,"*2nd*") -> 8 | BJ3: =COUNTIFS('Raw data'!$D:$D,"Build the Attack",'Raw data'!$P:$P,"*Direct play*",'Raw data'!$Y:$Y,"*2nd*") -> 9 | BK3: =COUNTIFS('Raw data'!$D:$D,"Build the Attack",'Raw data'!$P:$P,"*Reach Opp Half*",'Raw data'!$Y:$Y,"*2nd*") -> 6 | BL3: =COUNTIFS('Raw data'!$D:$D,"Create the Attack",'Raw data'!$Y:$Y,"*2nd*") -> 21 | BM3: =COUNTIFS('Raw data'!$D:$D,"Create the Attack",'Raw data'!$R:$R,"+",'Raw data'!$Y:$Y,"*2nd*") -> 5 | BN3: =COUNTIFS('Raw data'!$D:$D,"Create the Attack",'Raw data'!$R:$R,"-",'Raw data'!$Y:$Y,"*2nd*") -> 16 | BO3: =BM3/BL3 -> 0.23809524 | BP3: =BN3/BL3 -> 0.76190476 | BQ3: =COUNTIFS('Raw data'!$D:$D,"P'Boro Cross",'Raw data'!$Y:$Y,"*2nd*") -> 5 | BR3: =COUNTIFS('Raw data'!$D:$D,"P'Boro Cross",'Raw data'!$R:$R,"+",'Raw data'!$Y:$Y,"*2nd*") -> 1 | BS3: =COUNTIFS('Raw data'!$D:$D,"P'Boro Cross",'Raw data'!$R:$R,"-",'Raw data'!$Y:$Y,"*2nd*") -> 4 | BT3: =BR3/BQ3 -> 0.2 | BU3: =BS3/BQ3 -> 0.8 | BV3: =COUNTIFS('Raw data'!$D:$D,"Opp Cross",'Raw data'!$Y:$Y,"*2nd*") -> 10 | BW3: =COUNTIFS('Raw data'!$D:$D,"Opp Cross",'Raw data'!$R:$R,"+",'Raw data'!$Y:$Y,"*2nd*") -> 6 | BX3: =COUNTIFS('Raw data'!$D:$D,"Opp Cross",'Raw data'!$R:$R,"-",'Raw data'!$Y:$Y,"*2nd*") -> 4 | BY3: =BW3/BV3 -> 0.6 | BZ3: =BX3/BV3 -> 0.4 | CA3: =COUNTIFS('Raw data'!$D:$D,"High Block",'Raw data'!$Y:$Y,"*2nd*") -> 2 | CB3: =COUNTIFS('Raw data'!$D:$D,"High Block",'Raw data'!$R:$R,"+",'Raw data'!$Y:$Y,"*2nd*") -> 1 | CC3: =COUNTIFS('Raw data'!$D:$D,"High Block",'Raw data'!$R:$R,"-",'Raw data'!$Y:$Y,"*2nd*") -> 1 | CD3: =CB3/CA3 -> 0.5 | CE3: =CC3/CA3 -> 0.5 | CF3: =COUNTIFS('Raw data'!$D:$D,"High Block",'Raw data'!$S:$S,"Regain Opp Half",'Raw data'!$Y:$Y,"*2nd*") -> 1 | CG3: =COUNTIFS('Raw data'!$D:$D,"High Block",'Raw data'!$S:$S,"Force error",'Raw data'!$Y:$Y,"*2nd*") -> 0 | CH3: =COUNTIFS('Raw data'!$D:$D,"High Block",'Raw data'!$P:$P,"Direct play",'Raw data'!$Y:$Y,"*2nd*") -> 1 | CI3: =COUNTIFS('Raw data'!$D:$D,"Mid Block",'Raw data'!$Y:$Y,"*2nd*") -> 7 | CJ3: =COUNTIFS('Raw data'!$D:$D,"Mid Block",'Raw data'!$R:$R,"+",'Raw data'!$Y:$Y,"*2nd*") -> 5 | CK3: =COUNTIFS('Raw data'!$D:$D,"Mid Block",'Raw data'!$R:$R,"-",'Raw data'!$Y:$Y,"*2nd*") -> 2 | CL3: =CJ3/CI3 -> 0.71428571 | CM3: =CK3/CI3 -> 0.28571429 | CN3: =COUNTIFS('Raw data'!$D:$D,"Low Block",'Raw data'!$Y:$Y,"*2nd*") -> 5 | CO3: =COUNTIFS('Raw data'!$D:$D,"Low Block",'Raw data'!$R:$R,"+",'Raw data'!$Y:$Y,"*2nd*") -> 4 | CP3: =COUNTIFS('Raw data'!$D:$D,"Low Block",'Raw data'!$R:$R,"-",'Raw data'!$Y:$Y,"*2nd*") -> 1 | CQ3: =CO3/CN3 -> 0.8 | CR3: =CP3/CN3 -> 0.2 | CS3: =SUM(CU3:CW3) -> 39 | CT3: =COUNTIFS('Raw data'!$D:$D,"Transition to Attack",'Raw data'!$U:$U,"*Transition to Att Counter*",'Raw data'!$Y:$Y,"*2nd*") -> 2 | CU3: =COUNTIFS('Raw data'!$D:$D,"Transition to Attack",'Raw data'!$U:$U,"*Final 1/3*",'Raw data'!$Y:$Y,"*2nd*") -> 1 | CV3: =COUNTIFS('Raw data'!$D:$D,"Transition to Attack",'Raw data'!$U:$U,"*Middle 1/3*",'Raw data'!$Y:$Y,"*2nd*") -> 10 | CW3: =COUNTIFS('Raw data'!$D:$D,"Transition to Attack",'Raw data'!$U:$U,"*Own 1/3*",'Raw data'!$Y:$Y,"*2nd*") -> 28 | CX3: =SUM(CZ3:DB3) -> 39 | CY3: =COUNTIFS('Raw data'!$D:$D,"Transition to Defense",'Raw data'!$U:$U,"*Transition to def counter*",'Raw data'!$Y:$Y,"*2nd*") -> 5 | CZ3: =COUNTIFS('Raw data'!$D:$D,"Transition to Defense",'Raw data'!$U:$U,"*Final 1/3*",'Raw data'!$Y:$Y,"*2nd*") -> 12 | DA3: =COUNTIFS('Raw data'!$D:$D,"Transition to Defense",'Raw data'!$U:$U,"*Middle 1/3*",'Raw data'!$Y:$Y,"*2nd*") -> 16 | DB3: =COUNTIFS('Raw data'!$D:$D,"Transition to Defense",'Raw data'!$U:$U,"*Own 1/3*",'Raw data'!$Y:$Y,"*2nd*") -> 11 | DC3: =COUNTIFS('Raw data'!$T:$T,"P'Boro Corner",'Raw data'!$Y:$Y,"*2nd*") -> 1 | DD3: =COUNTIFS('Raw data'!$T:$T,"Opp Corner",'Raw data'!$Y:$Y,"*2nd*") -> 3 | DE3: =COUNTIFS('Raw data'!$T:$T,"*P'Boro Throw in*",'Raw data'!$Y:$Y,"*2nd*") -> 5 | DF3: =COUNTIFS('Raw data'!$T:$T,"*P'Boro Throw in*",'Raw data'!$U:$U,"*Final 1/3*",'Raw data'!$Y:$Y,"*2nd*") -> 2 | DG3: =COUNTIFS('Raw data'!$T:$T,"*P'Boro Throw in*",'Raw data'!$U:$U,"*Middle 1/3*",'Raw data'!$Y:$Y,"*2nd*") -> 1 | DH3: =COUNTIFS('Raw data'!$T:$T,"*P'Boro Throw in*",'Raw data'!$U:$U,"*Own 1/3*",'Raw data'!$Y:$Y,"*2nd*") -> 2 | DI3: =COUNTIFS('Raw data'!$T:$T,"*Opp Throw in*",'Raw data'!$Y:$Y,"*2nd*") -> 13 | DJ3: =COUNTIFS('Raw data'!$T:$T,"*Opp Throw in*",'Raw data'!$U:$U,"*Own 1/3*",'Raw data'!$Y:$Y,"*2nd*") -> 5 | DK3: =COUNTIFS('Raw data'!$T:$T,"*Opp Throw in*",'Raw data'!$U:$U,"*Middle 1/3*",'Raw data'!$Y:$Y,"*2nd*") -> 5 | DL3: =COUNTIFS('Raw data'!$T:$T,"*Opp Throw in*",'Raw data'!$U:$U,"*Own 1/3*",'Raw data'!$Y:$Y,"*2nd*") -> 5 | DM3: =COUNTIFS('Raw data'!$T:$T,"P'Boro Free Kick",'Raw data'!$Y:$Y,"*2nd*") -> 7 | DN3: =COUNTIFS('Raw data'!$T:$T,"P'Boro Free kick",'Raw data'!$U:$U,"Final 1/3",'Raw data'!$Y:$Y,"*2nd*") -> 0 | DO3: =COUNTIFS('Raw data'!$T:$T,"Opp Free Kick",'Raw data'!$Y:$Y,"*2nd*") -> 6 | DP3: =COUNTIFS('Raw data'!$T:$T,"Opp Free kick",'Raw data'!$U:$U,"Final 1/3",'Raw data'!$Y:$Y,"*2nd*") -> 0 | DQ3: =COUNTIFS('Raw data'!$T:$T,"P'Boro Goal Kick",'Raw data'!$Y:$Y,"*2nd*") -> 4 | DR3: =COUNTIFS('Raw data'!$T:$T,"Opp Goal Kick",'Raw data'!$Y:$Y,"*2nd*") -> 4 | DS3: =SUM(DT3,DF3,CU3) -> 16 | DT3: =COUNTIFS('Raw data'!$D:$D,"P'Boro 1/3 Entry",'Raw data'!$Y:$Y,"*2nd*") -> 13 | DU3: =SUM(DJ3,DV3,DB3) -> 31 | DV3: =COUNTIFS('Raw data'!$D:$D,"Opp 1/3 Entry",'Raw data'!$Y:$Y,"*2nd*") -> 15 | DW3: =SUM(DS3,DU3) -> 47 | DX3: =COUNTIFS('Raw data'!$D:$D,"P'Boro Touches in Box",'Raw data'!$Y:$Y,"*2nd*") -> 6 | DY3: =COUNTIFS('Raw data'!$D:$D,"Opp Touches in Box",'Raw data'!$Y:$Y,"*2nd*") -> 11 | DZ3: =SUM(DX3:DY3) -> 17 | EA3: =SUM(EA26:EA39) -> 175 | EB3: =SUM(EB26:EB39) -> 138 | EC3: =SUM(EC26:EC39) -> 37 | ED3: =IFERROR(EB3/EA3,"-") -> 0.78857143 | EE3: =IFERROR(EC3/EA3,"-") -> 0.21142857 | EF3: =SUM(EF26:EF39) -> 91 | EG3: =SUM(EG26:EG39) -> 61 | EH3: =SUM(EH26:EH39) -> 30 | EI3: =IFERROR(EG3/EF3,"-") -> 0.67032967 | EJ3: =IFERROR(EH3/EF3,"-") -> 0.32967033 | EK3: =SUM(EK26:EK39) -> 34 | EL3: =SUM(EL26:EL39) -> 28 | EM3: =SUM(EM26:EM39) -> 6 | EN3: =IFERROR(EL3/EK3,"-") -> 0.82352941 | EO3: =IFERROR(EM3/EK3,"-") -> 0.17647059 | EP3: =SUM(EP26:EP39) -> 50 | EQ3: =SUM(EQ26:EQ39) -> 49 | ER3: =SUM(ER26:ER39) -> 1 | ES3: =IFERROR(EQ3/EP3,"-") -> 0.98 | ET3: =IFERROR(ER3/EP3,"-") -> 0.02 | EU3: =SUM(EU26:EU39) -> 21 | EV3: =SUM(EV26:EV39) -> 12 | EW3: =SUM(EW26:EW39) -> 9 | EX3: =IFERROR(EV3/EU3,"-") -> 0.57142857 | EY3: =IFERROR(EW3/EU3,"-") -> 0.42857143 | EZ3: =SUM(EZ26:EZ39) -> 9 | FA3: =SUM(FA26:FA39) -> 3 | FB3: =SUM(FB26:FB39) -> 6 | FC3: =IFERROR(FA3/EZ3,"-") -> 0.33333333 | FD3: =IFERROR(FB3/EZ3,"-") -> 0.66666667 | FE3: =SUM(FE26:FE39) -> 3 | FF3: =SUM(FF26:FF39) -> 0 | FG3: =SUM(FG26:FG39) -> 0 | FH3: =SUM(FH26:FH39) -> 0 | FI3: =IFERROR(FG3/FF3,"-") -> - | FJ3: =IFERROR(FH3/FF3,"-") -> - | FK3: =SUM(FK26:FK39) -> 133 | FL3: =SUM(FL26:FL39) -> 86 | FM3: =SUM(FM26:FM39) -> 26 | FN3: =SUM(FN26:FN39) -> 17 | FO3: =SUM(FO26:FO39) -> 20 | FP3: =SUM(FP26:FP39) -> 4 | FQ3: =SUM(FQ26:FQ39) -> 10 | FR3: =SUM(FR26:FR39) -> 6 | ... FV3: =SUM(FV26:FV39) -> 2 | FW3: =IFERROR(FU3/FT3,"-") -> 0.88235294 | FX3: =IFERROR(FV3/FT3,"-") -> 0.11764706 | FY3: =SUM(FY26:FY39) -> 5 | FZ3: =SUM(FZ26:FZ39) -> 1 | GA3: =SUM(GA26:GA39) -> 4 | GB3: =IFERROR(FZ3/FY3,"-") -> 0.2 | GC3: =IFERROR(GA3/FY3,"-") -> 0.8 | GD3: =SUM(GD26:GD39) -> 4 | GE3: =SUM(GE26:GE39) -> 2 | GF3: =SUM(GF26:GF39) -> 2 | GG3: =SUM(GG26:GG39) -> 0 | GH3: =SUM(GH26:GH39) -> 2 | GI3: =SUM(GI26:GI39) -> 2 | GJ3: =SUM(GJ26:GJ39) -> 11 | GK3: =SUM(GK26:GK39) -> 9 | GL3: =SUM(GL26:GL39) -> 2 | GM3: =IFERROR(GK3/GJ3,"-") -> 0.81818182 | GN3: =IFERROR(GL3/GJ3,"-") -> 0.18181818 | GO3: =SUM(GO26:GO39) -> 9 | GP3: =SUM(GP26:GP39) -> 15 | GQ3: =SUM(GQ26:GQ39) -> 26 | GR3: =SUM(GR26:GR39) -> 8 | GS3: =SUM(GS26:GS39) -> 0 | GT3: =SUM(GT26:GT39) -> 3 | GU3: =SUM(GU26:GU39) -> 0 | GV3: =SUM(GV26:GV39) -> 42 | ... GX3: =SUM(GX26:GX39) -> 21 | GY3: =IFERROR(GW3/GV3,"-") -> 0.47619048 | GZ3: =IFERROR(GX3/GV3,"-") -> 0.5 | HA3: =SUM(HA26:HA39) -> 23 | HB3: =SUM(HB26:HB39) -> 5 | HC3: =SUM(HC26:HC39) -> 17 | HD3: =IFERROR(HB3/HA3,"-") -> 0.2173913 | HE3: =IFERROR(HC3/HA3,"-") -> 0.73913043 | HF3: =SUM(HF26:HF39) -> 8 | HG3: =SUM(HG26:HG39) -> 6 | HH3: =SUM(HH26:HH39) -> 2 | HI3: =IFERROR(HG3/HF3,"-") -> 0.75 | HJ3: =IFERROR(HH3/HF3,"-") -> 0.25 | HK3: =SUM(HK26:HK39) -> 5 | HL3: =SUM(HL26:HL39) -> 3 | HM3: =SUM(HM26:HM39) -> 2 | HN3: =IFERROR(HL3/HK3,"-") -> 0.6 | HO3: =IFERROR(HM3/HK3,"-") -> 0.4 | HP3: =SUM(HP26:HP39) -> 4 | HQ3: =SUM(HQ26:HQ39) -> 4 | HR3: =SUM(HR26:HR39) -> 0 | HS3: =IFERROR(HQ3/HP3,"-") -> 1 | HT3: =IFERROR(HR3/HP3,"-") -> 0 | HU3: =SUM(HU26:HU39) -> 5 | HV3: =SUM(HV26:HV39) -> 2 | HW3: =SUM(HW26:HW39) -> 3 | HX3: =IFERROR(HV3/HU3,"-") -> 0.4 | HY3: =IFERROR(HW3/HU3,"-") -> 0.6 | HZ3: =SUM(HZ26:HZ39) -> 6 | IA3: =SUM(IA26:IA39) -> 14 | IB3: =SUM(IB26:IB39) -> 9 | IC3: =SUM(IC26:IC39) -> 5 | ID3: =SUM(ID26:ID39) -> 4 | IE3: =SUM(IE26:IE39) -> 4 | IF3: =SUM(IF26:IF39) -> 7 | IG3: =SUM(IG26:IG39) -> 3 | ... IO3: =SUM(IO26:IO39) -> 1
E4: Peterborough | F4: Onside Academy | G4: H | H4: Preseason | I4: 1-4-3-3 | J4: Full time | K4: Full time | L4: {=_xlfn.IFS(M4<N4,"L",M4=N4,"D",M4>N4,"W")} -> D | M4: =COUNTIF('Raw data'!$D:$D,"P'Boro Goal") -> 4 | N4: =COUNTIF('Raw data'!$D:$D,"Opp Goal") -> 4 | O4: =P4+Q4 -> 86.043264 | P4: =SUMIF('Raw data'!$D:$D,"Ball in Play",'Raw data'!$C:$C)/60 -> 51.342596 | Q4: =SUMIF('Raw data'!$D:$D,"Out of Play",'Raw data'!$C:$C)/60 -> 34.700668 | R4: =P4/O4 -> 0.59670674 | S4: =Q4/O4 -> 0.40329326 | T4: =(SUMIF('Raw data'!$D:$D,"In Possession",'Raw data'!$C:$C)-(3*(COUNTIF('Raw data'!$D:$D,"In Possession"))))/60 -> 31.338559 | U4: =(SUMIF('Raw data'!$D:$D,"Out of Possession",'Raw data'!$C:$C)-(3*(COUNTIF('Raw data'!$D:$D,"Out of Possession"))))/60 -> 20.513892 | V4: =T4/(T4+U4) -> 0.60437951 | W4: =U4/(T4+U4) -> 0.39562049 | X4: =COUNTIF('Raw data'!$D:$D,"P'Boro Chance") -> 12 | Y4: =SUM(Z4:AB4) -> 11 | Z4: =COUNTIFS('Raw data'!$D:$D,"P'Boro Chance",'Raw data'!$Q:$Q,"*On Target*") -> 5 | AA4: =COUNTIFS('Raw data'!$D:$D,"P'Boro Chance",'Raw data'!$Q:$Q,"*Off Target*") -> 3 | AB4: =COUNTIFS('Raw data'!$D:$D,"P'Boro Chance",'Raw data'!$Q:$Q,"*Blocked*") -> 3 | AC4: =Z4/Y4 -> 0.45454545 | AD4: =AA4/Y4 -> 0.27272727 | AE4: =AB4/Y4 -> 0.27272727 | AF4: =COUNTIFS('Raw data'!$D:$D,"P'Boro Chance",'Raw data'!$Q:$Q,"*Shots in the box*") -> 8 | AG4: =COUNTIFS('Raw data'!$D:$D,"P'Boro Chance",'Raw data'!$Q:$Q,"*Shots from Open Play*") -> 4 | AH4: =COUNTIFS('Raw data'!$D:$D,"P'Boro Chance",'Raw data'!$Q:$Q,"*Cross to Shots*") -> 2 | AI4: =COUNTIFS('Raw data'!$D:$D,"P'Boro Chance",'Raw data'!$Q:$Q,"*Counterattack to Shots*") -> 3 | AJ4: =COUNTIFS('Raw data'!$D:$D,"P'Boro Chance",'Raw data'!$Q:$Q,"*Through Pass to Shots*") -> 3 | AK4: =COUNTIFS('Raw data'!$D:$D,"P'Boro Chance",'Raw data'!$Q:$Q,"*Shots from Transition*") -> 5 | AL4: =COUNTIFS('Raw data'!$D:$D,"P'Boro Chance",'Raw data'!$Q:$Q,"*Shots from Set Play*") -> 1 | AM4: =COUNTIFS('Raw data'!$D:$D,"P'Boro Chance",'Raw data'!$Q:$Q,"*Shots from Restart*") -> 2 | AN4: =COUNTIF('Raw data'!$D:$D,"Opp Chance") -> 25 | AO4: =SUM(AP4:AR4) -> 23 | AP4: =COUNTIFS('Raw data'!$D:$D,"Opp Chance",'Raw data'!$Q:$Q,"*On Target*") -> 10 | AQ4: =COUNTIFS('Raw data'!$D:$D,"Opp Chance",'Raw data'!$Q:$Q,"*Off Target*") -> 10 | AR4: =COUNTIFS('Raw data'!$D:$D,"Opp Chance",'Raw data'!$Q:$Q,"*Blocked*") -> 3 | AS4: =AP4/AO4 -> 0.43478261 | AT4: =AQ4/AO4 -> 0.43478261 | AU4: =AR4/AO4 -> 0.13043478 | AV4: =COUNTIFS('Raw data'!$D:$D,"Opp Chance",'Raw data'!$Q:$Q,"*Shots in the box*") -> 12 | AW4: =COUNTIFS('Raw data'!$D:$D,"Opp Chance",'Raw data'!$Q:$Q,"*Shots from Open Play*") -> 4 | AX4: =COUNTIFS('Raw data'!$D:$D,"Opp Chance",'Raw data'!$Q:$Q,"*Cross to Shots*") -> 4 | AY4: =COUNTIFS('Raw data'!$D:$D,"Opp Chance",'Raw data'!$Q:$Q,"*Counterattack to Shots*") -> 2 | AZ4: =COUNTIFS('Raw data'!$D:$D,"Opp Chance",'Raw data'!$Q:$Q,"*Through Pass to Shots*") -> 3 | BA4: =COUNTIFS('Raw data'!$D:$D,"Opp Chance",'Raw data'!$Q:$Q,"*Shots from Transition*") -> 17 | BB4: =COUNTIFS('Raw data'!$D:$D,"Opp Chance",'Raw data'!$Q:$Q,"*Shots from Set Play*") -> 2 | BC4: =COUNTIFS('Raw data'!$D:$D,"Opp Chance",'Raw data'!$Q:$Q,"*Shots from Restart*") -> 2 | BD4: =COUNTIF('Raw data'!$D:$D,"Build the Attack") -> 47 | BE4: =COUNTIFS('Raw data'!$D:$D,"Build the Attack",'Raw data'!$R:$R,"*+*") -> 18 | BF4: =COUNTIFS('Raw data'!$D:$D,"Build the Attack",'Raw data'!$R:$R,"-") -> 29 | BG4: =BE4/BD4 -> 0.38297872 | BH4: =BF4/BD4 -> 0.61702128 | BI4: =COUNTIFS('Raw data'!$D:$D,"Build the Attack",'Raw data'!$P:$P,"*Turnover*") -> 15 | BJ4: =COUNTIFS('Raw data'!$D:$D,"Build the Attack",'Raw data'!$P:$P,"*Direct play*") -> 18 | BK4: =COUNTIFS('Raw data'!$D:$D,"Build the Attack",'Raw data'!$P:$P,"*Reach Opp Half*") -> 12 | BL4: =COUNTIF('Raw data'!$D:$D,"Create the Attack") -> 42 | BM4: =COUNTIFS('Raw data'!$D:$D,"Create the Attack",'Raw data'!$R:$R,"+") -> 12 | BN4: =COUNTIFS('Raw data'!$D:$D,"Create the Attack",'Raw data'!$R:$R,"-") -> 30 | BO4: =BM4/BL4 -> 0.28571429 | BP4: =BN4/BL4 -> 0.71428571 | BQ4: =COUNTIF('Raw data'!$D:$D,"P'Boro Cross") -> 11 | BR4: =COUNTIFS('Raw data'!$D:$D,"P'Boro Cross",'Raw data'!$R:$R,"+") -> 3 | BS4: =COUNTIFS('Raw data'!$D:$D,"P'Boro Cross",'Raw data'!$R:$R,"-") -> 8 | BT4: =BR4/BQ4 -> 0.27272727 | BU4: =BS4/BQ4 -> 0.72727273 | BV4: =COUNTIF('Raw data'!$D:$D,"Opp Cross") -> 14 | BW4: =COUNTIFS('Raw data'!$D:$D,"Opp Cross",'Raw data'!$R:$R,"+") -> 7 | BX4: =COUNTIFS('Raw data'!$D:$D,"Opp Cross",'Raw data'!$R:$R,"-") -> 7 | BY4: =BW4/BV4 -> 0.5 | BZ4: =BX4/BV4 -> 0.5 | CA4: =COUNTIF('Raw data'!$D:$D,"High Block") -> 3 | CB4: =COUNTIFS('Raw data'!$D:$D,"High Block",'Raw data'!$R:$R,"+") -> 2 | CC4: =COUNTIFS('Raw data'!$D:$D,"High Block",'Raw data'!$R:$R,"-") -> 1 | CD4: =CB4/CA4 -> 0.66666667 | CE4: =CC4/CA4 -> 0.33333333 | CF4: =COUNTIFS('Raw data'!$D:$D,"High Block",'Raw data'!$S:$S,"Regain Opp Half") -> 1 | CG4: =COUNTIFS('Raw data'!$D:$D,"High Block",'Raw data'!$S:$S,"Force error") -> 1 | CH4: =COUNTIFS('Raw data'!$D:$D,"High Block",'Raw data'!$P:$P,"Direct play") -> 1 | CI4: =COUNTIF('Raw data'!$D:$D,"Mid Block") -> 7 | CJ4: =COUNTIFS('Raw data'!$D:$D,"Mid Block",'Raw data'!$R:$R,"+") -> 5 | CK4: =COUNTIFS('Raw data'!$D:$D,"Mid Block",'Raw data'!$R:$R,"-") -> 2 | CL4: =CJ4/CI4 -> 0.71428571 | CM4: =CK4/CI4 -> 0.28571429 | CN4: =COUNTIF('Raw data'!$D:$D,"Low Block") -> 5 | CO4: =COUNTIFS('Raw data'!$D:$D,"Low Block",'Raw data'!$R:$R,"+") -> 4 | CP4: =COUNTIFS('Raw data'!$D:$D,"Low Block",'Raw data'!$R:$R,"-") -> 1 | CQ4: =CO4/CN4 -> 0.8 | CR4: =CP4/CN4 -> 0.2 | CS4: =SUM(CU4:CW4) -> 69 | CT4: =COUNTIFS('Raw data'!$D:$D,"Transition to Attack",'Raw data'!$U:$U,"*Transition to Att Counter*") -> 5 | CU4: =COUNTIFS('Raw data'!$D:$D,"Transition to Attack",'Raw data'!$U:$U,"*Final 1/3*") -> 1 | CV4: =COUNTIFS('Raw data'!$D:$D,"Transition to Attack",'Raw data'!$U:$U,"*Middle 1/3*") -> 27 | CW4: =COUNTIFS('Raw data'!$D:$D,"Transition to Attack",'Raw data'!$U:$U,"*Own 1/3*") -> 41 | CX4: =SUM(CZ4:DB4) -> 75 | CY4: =COUNTIFS('Raw data'!$D:$D,"Transition to Defense",'Raw data'!$U:$U,"*Transition to def counter*") -> 6 | CZ4: =COUNTIFS('Raw data'!$D:$D,"Transition to Defense",'Raw data'!$U:$U,"*Final 1/3*") -> 24 | DA4: =COUNTIFS('Raw data'!$D:$D,"Transition to Defense",'Raw data'!$U:$U,"*Middle 1/3*") -> 30 | DB4: =COUNTIFS('Raw data'!$D:$D,"Transition to Defense",'Raw data'!$U:$U,"*Own 1/3*") -> 21 | DC4: =COUNTIF('Raw data'!$T:$T,"P'Boro Corner") -> 1 | DD4: =COUNTIF('Raw data'!$T:$T,"Opp Corner") -> 5 | DE4: =COUNTIF('Raw data'!$T:$T,"*P'Boro Throw in*") -> 12 | DF4: =COUNTIFS('Raw data'!$T:$T,"*P'Boro Throw in*",'Raw data'!$U:$U,"*Final 1/3*") -> 6 | DG4: =COUNTIFS('Raw data'!$T:$T,"*P'Boro Throw in*",'Raw data'!$U:$U,"*Middle 1/3*") -> 2 | DH4: =COUNTIFS('Raw data'!$T:$T,"*P'Boro Throw in*",'Raw data'!$U:$U,"*Own 1/3*") -> 4 | DI4: =COUNTIF('Raw data'!$T:$T,"*Opp Throw in*") -> 24 | DJ4: =COUNTIFS('Raw data'!$T:$T,"*Opp Throw in*",'Raw data'!$U:$U,"*Own 1/3*") -> 9 | DK4: =COUNTIFS('Raw data'!$T:$T,"*Opp Throw in*",'Raw data'!$U:$U,"*Middle 1/3*") -> 6 | DL4: =COUNTIFS('Raw data'!$T:$T,"*Opp Throw in*",'Raw data'!$U:$U,"*Own 1/3*") -> 9 | DM4: =COUNTIF('Raw data'!$T:$T,"P'Boro Free Kick") -> 12 | DN4: =COUNTIFS('Raw data'!$T:$T,"P'Boro Free kick",'Raw data'!$U:$U,"Final 1/3") -> 0 | DO4: =COUNTIF('Raw data'!$T:$T,"Opp Free Kick") -> 10 | DP4: =COUNTIFS('Raw data'!$T:$T,"Opp Free kick",'Raw data'!$U:$U,"Final 1/3") -> 0 | DQ4: =COUNTIFS('Raw data'!$T:$T,"P'Boro Goal Kick") -> 15 | DR4: =COUNTIFS('Raw data'!$T:$T,"Opp Goal Kick") -> 9 | DS4: =SUM(DT4,DF4,CU4) -> 35 | DT4: =COUNTIF('Raw data'!$D:$D,"P'Boro 1/3 Entry") -> 28 | DU4: =SUM(DJ4,DV4,DB4) -> 54 | DV4: =COUNTIF('Raw data'!$D:$D,"Opp 1/3 Entry") -> 24 | DW4: =SUM(DS4,DU4) -> 89 | DX4: =COUNTIF('Raw data'!$D:$D,"P'Boro Touches in Box") -> 13 | DY4: =COUNTIF('Raw data'!$D:$D,"Opp Touches in Box") -> 18 | DZ4: =SUM(DX4:DY4) -> 31 | EA4: =SUM(EA42:EA56) -> 388 | EB4: =SUM(EB42:EB56) -> 293 | EC4: =SUM(EC42:EC56) -> 95 | ED4: =IFERROR(EB4/EA4,"-") -> 0.75515464 | EE4: =IFERROR(EC4/EA4,"-") -> 0.24484536 | EF4: =SUM(EF42:EF56) -> 193 | EG4: =SUM(EG42:EG56) -> 116 | EH4: =SUM(EH42:EH56) -> 77 | EI4: =IFERROR(EG4/EF4,"-") -> 0.60103627 | EJ4: =IFERROR(EH4/EF4,"-") -> 0.39896373 | EK4: =SUM(EK42:EK56) -> 90 | EL4: =SUM(EL42:EL56) -> 77 | EM4: =SUM(EM42:EM56) -> 13 | EN4: =IFERROR(EL4/EK4,"-") -> 0.85555556 | EO4: =IFERROR(EM4/EK4,"-") -> 0.14444444 | EP4: =SUM(EP42:EP56) -> 105 | EQ4: =SUM(EQ42:EQ56) -> 100 | ER4: =SUM(ER42:ER56) -> 5 | ES4: =IFERROR(EQ4/EP4,"-") -> 0.95238095 | ET4: =IFERROR(ER4/EP4,"-") -> 0.047619048 | EU4: =SUM(EU42:EU56) -> 43 | EV4: =SUM(EV42:EV56) -> 20 | EW4: =SUM(EW42:EW56) -> 24 | EX4: =IFERROR(EV4/EU4,"-") -> 0.46511628 | EY4: =IFERROR(EW4/EU4,"-") -> 0.55813953 | EZ4: =SUM(EZ42:EZ56) -> 23 | FA4: =SUM(FA42:FA56) -> 10 | FB4: =SUM(FB42:FB56) -> 14 | FC4: =IFERROR(FA4/EZ4,"-") -> 0.43478261 | FD4: =IFERROR(FB4/EZ4,"-") -> 0.60869565 | FE4: =SUM(FE42:FE56) -> 7 | FF4: =SUM(FF42:FF56) -> 0 | FG4: =SUM(FG42:FG56) -> 0 | FH4: =SUM(FH42:FH56) -> 0 | FI4: =IFERROR(FG4/FF4,"-") -> - | FJ4: =IFERROR(FH4/FF4,"-") -> - | FK4: =SUM(FK42:FK56) -> 272 | FL4: =SUM(FL42:FL56) -> 179 | FM4: =SUM(FM42:FM56) -> 64 | FN4: =SUM(FN42:FN56) -> 28 | FO4: =SUM(FO42:FO56) -> 31 | FP4: =SUM(FP42:FP56) -> 7 | FQ4: =SUM(FQ42:FQ56) -> 15 | FR4: =SUM(FR42:FR56) -> 9 | ... FV4: =SUM(FV42:FV56) -> 2 | FW4: =IFERROR(FU4/FT4,"-") -> 0.91304348 | FX4: =IFERROR(FV4/FT4,"-") -> 0.086956522 | FY4: =SUM(FY42:FY56) -> 12 | FZ4: =SUM(FZ42:FZ56) -> 2 | GA4: =SUM(GA42:GA56) -> 10 | GB4: =IFERROR(FZ4/FY4,"-") -> 0.16666667 | GC4: =IFERROR(GA4/FY4,"-") -> 0.83333333 | GD4: =SUM(GD42:GD56) -> 10 | GE4: =SUM(GE42:GE56) -> 4 | GF4: =SUM(GF42:GF56) -> 3 | GG4: =SUM(GG42:GG56) -> 3 | GH4: =SUM(GH42:GH56) -> 4 | GI4: =SUM(GI42:GI56) -> 5 | GJ4: =SUM(GJ42:GJ56) -> 19 | GK4: =SUM(GK42:GK56) -> 17 | GL4: =SUM(GL42:GL56) -> 2 | GM4: =IFERROR(GK4/GJ4,"-") -> 0.89473684 | GN4: =IFERROR(GL4/GJ4,"-") -> 0.10526316 | GO4: =SUM(GO42:GO56) -> 21 | GP4: =SUM(GP42:GP56) -> 35 | GQ4: =SUM(GQ42:GQ56) -> 57 | GR4: =SUM(GR42:GR56) -> 13 | GS4: =SUM(GS42:GS56) -> 1 | GT4: =SUM(GT42:GT56) -> 9 | GU4: =SUM(GU42:GU56) -> 0 | GV4: =SUM(GV42:GV56) -> 74 | ... GX4: =SUM(GX42:GX56) -> 34 | GY4: =IFERROR(GW4/GV4,"-") -> 0.52702703 | GZ4: =IFERROR(GX4/GV4,"-") -> 0.45945946 | HA4: =SUM(HA42:HA56) -> 35 | HB4: =SUM(HB42:HB56) -> 11 | HC4: =SUM(HC42:HC56) -> 23 | HD4: =IFERROR(HB4/HA4,"-") -> 0.31428571 | HE4: =IFERROR(HC4/HA4,"-") -> 0.65714286 | HF4: =SUM(HF42:HF56) -> 20 | HG4: =SUM(HG42:HG56) -> 11 | HH4: =SUM(HH42:HH56) -> 9 | HI4: =IFERROR(HG4/HF4,"-") -> 0.55 | HJ4: =IFERROR(HH4/HF4,"-") -> 0.45 | HK4: =SUM(HK42:HK56) -> 9 | HL4: =SUM(HL42:HL56) -> 6 | HM4: =SUM(HM42:HM56) -> 3 | HN4: =IFERROR(HL4/HK4,"-") -> 0.66666667 | HO4: =IFERROR(HM4/HK4,"-") -> 0.33333333 | HP4: =SUM(HP42:HP56) -> 9 | HQ4: =SUM(HQ42:HQ56) -> 9 | HR4: =SUM(HR42:HR56) -> 0 | HS4: =IFERROR(HQ4/HP4,"-") -> 1 | HT4: =IFERROR(HR4/HP4,"-") -> 0 | HU4: =SUM(HU42:HU56) -> 15 | HV4: =SUM(HV42:HV56) -> 8 | HW4: =SUM(HW42:HW56) -> 7 | HX4: =IFERROR(HV4/HU4,"-") -> 0.53333333 | HY4: =IFERROR(HW4/HU4,"-") -> 0.46666667 | HZ4: =SUM(HZ42:HZ56) -> 11 | IA4: =SUM(IA42:IA56) -> 26 | IB4: =SUM(IB42:IB56) -> 20 | IC4: =SUM(IC42:IC56) -> 13 | ID4: =SUM(ID42:ID56) -> 6 | IE4: =SUM(IE42:IE56) -> 4 | IF4: =SUM(IF42:IF56) -> 12 | IG4: =SUM(IG42:IG56) -> 6 | ... IO4: =SUM(IO42:IO56) -> 2
